Workbook

Sheet Resumen
B1: MATRIZ DE CUMPLIMIENTO DE LAS CARRERAS.
A2: Nro. | B2: CARRERA | C2: DIRECTOR/A | D2: POA | E2: INFORME SEMESTRAL | F2: MATRIZ SEMESTRAL | G2: INFORME FINAL | H2: MATRIZ FINAL | I2: EVIDENCIAS | T2: Observación | U2: %Avance poa
I3: Estrategia 1 | M3: Estrategia 2 | P3: Estrategia 3 | S3: Estrategia 4
I4: Objetivo 1 | J4: Objetivo 2 | K4: Objetivo 3 | L4: Objetivo 4 | M4: Objetivo 1 | N4: Objetivo 2 | O4: Objetivo 3 | P4: Objetivo 1 | Q4: Objetivo 2 | R4: Objetivo 3 | S4: Objetivo 1
A5: 1 | B5: gid=800026368 | C5: Mgtr. Jorge Jetón | D5: ENTREGADO | E5: ENTREGADO | F5: ENTREGADO | G5: S/N | H5: S/N | I5: X | J5: X | K5: X | L5: X | M5: X | N5: X | O5: X | P5: X | Q5: X | R5: X | S5: X | T5: EVIDENCIAS POR COMPLETAR SEGUNDO SEMESTRE | U5: ='Entrenamiento Deportivo'!$I$59 -> 0.82894737
A6: 2 | B6: gid=684874196 | C6: Dra. Germania Díaz | D6: ENTREGADO | E6: ENTREGADO | F6: ENTREGADO | G6: S/N | H6: S/N | I6: X | J6: X | K6: x | L6: x | M6: x | N6: x | O6: X | P6: X | Q6: X | R6: X | S6: X | T6: EVIDENCIAS POR COMPLETAR SEGUNDO SEMESTRE | U6: =Penitenciaria!$I$59 -> 0.84789474
A7: 3 | B7: gid=1295587340 | C7: Mgtr. Paola Urgilés | D7: ENTREGADO | E7: ENTREGADO | F7: ENTREGADO | G7: S/N | H7: S/N | I7: X | J7: X | K7: x | L7: x | M7: x | N7: x | O7: X | P7: X | Q7: X | R7: X | S7: X | T7: EVIDENCIAS POR COMPLETAR SEGUNDO SEMESTRE | U7: ='Producción Audiovisual'!$I$60 -> 0.53947368
A8: 4 | B8: gid=975999619 | C8: Mgtr. Mónica Galarza | D8: ENTREGADO | E8: ENTREGADO | F8: ENTREGADO | G8: S/N | H8: S/N | I8: X | J8: X | K8: x | L8: x | M8: x | N8: x | O8: X | P8: X | Q8: X | R8: X | S8: X | T8: EVIDENCIAS POR COMPLETAR SEGUNDO SEMESTRE | U8: ='Plataformas tecnológicas'!$I$59 -> 0.97815789
A9: 5 | B9: gid=78273914 | C9: Mgtr. Priscila Bernal | D9: ENTREGADO | E9: ENTREGADO | F9: ENTREGADO | G9: S/N | H9: S/N | I9: X | J9: X | K9: x | L9: x | M9: x | N9: x | O9: X | P9: X | Q9: X | R9: X | S9: X | T9: EVIDENCIAS POR COMPLETAR SEGUNDO SEMESTRE | U9: ='Biga Data'!$I$59 -> 0.875
A10: 6 | B10: gid=691242759 | C10: Mgtr. Priscila Bernal | D10: ENTREGADO | E10: ENTREGADO | F10: ENTREGADO | G10: S/N | H10: S/N | I10: X | J10: X | K10: x | L10: x | M10: x | N10: x | O10: X | P10: X | Q10: X | R10: X | S10: X | T10: EVIDENCIAS POR COMPLETAR SEGUNDO SEMESTRE | U10: =Ciberseguridad!$I$59 -> 0.97368421
A11: 7 | B11: gid=149880824 | C11: Mgtr. Verónica Segarra | D11: ENTREGADO | E11: ENTREGADO | F11: ENTREGADO | G11: S/N | H11: S/N | I11: X | J11: X | K11: x | L11: x | M11: x | N11: x | O11: X | P11: X | Q11: X | R11: X | S11: X | T11: EVIDENCIAS POR COMPLETAR SEGUNDO SEMESTRE | U11: =Software!$I$59 -> 0.84210526
A12: 8 | B12: gid=209077879 | C12: Mgtr. Catherine Alvear | D12: ENTREGADO | E12: ENTREGADO | F12: ENTREGADO | G12: S/N | H12: S/N | I12: X | J12: X | K12: x | L12: x | M12: x | N12: x | O12: X | P12: X | Q12: X | R12: X | S12: X | T12: EVIDENCIAS POR COMPLETAR SEGUNDO SEMESTRE | U12: ='Desarrollo infantil'!$I$59 -> 0.44736842
A13: 9 | B13: gid=1706091479 | C13: Mgtr. Fernanda Manosalvas | D13: ENTREGADO | E13: ENTREGADO | F13: ENTREGADO | G13: S/N | H13: S/N | I13: X | J13: X | K13: x | L13: x | M13: x | N13: x | O13: X | P13: X | Q13: X | R13: X | S13: X | T13: EVIDENCIAS POR COMPLETAR SEGUNDO SEMESTRE | U13: =Patrimonio!$I$59 -> 0.43684211
A14: 10 | B14: gid=2051595220 | C14: Mgtr. Adrián Criollo | D14: ENTREGADO | E14: ENTREGADO | F14: ENTREGADO | G14: S/N | H14: S/N | I14: X | J14: X | K14: x | L14: x | M14: x | N14: x | O14: X | P14: X | Q14: X | R14: X | S14: X | T14: EVIDENCIAS POR COMPLETAR SEGUNDO SEMESTRE | U14: ='Mantenimiento eléctrico'!$I$59 -> 0.86315789
A15: 11 | B15: gid=1027498431 | C15: Mgtr. Ivan Vera | D15: ENTREGADO | E15: ENTREGADO | F15: ENTREGADO | G15: S/N | H15: S/N | I15: X | J15: X | K15: x | L15: x | M15: x | N15: x | O15: X | P15: X | Q15: X | R15: X | S15: X | T15: EVIDENCIAS POR COMPLETAR SEGUNDO SEMESTRE | U15: =Mecatrónica!$I$59 -> 0.82894737
A16: 12 | B16: gid=742744125 | C16: Mgtr. Pablo Narváez | D16: ENTREGADO | E16: ENTREGADO | F16: ENTREGADO | G16: S/N | H16: S/N | I16: X | J16: X | K16: X | L16: X | M16: X | N16: X | O16: X | P16: X | Q16: X | R16: X | S16: X | T16: EVIDENCIAS POR COMPLETAR SEGUNDO SEMESTRE | U16: =Metalmecánica!$I$59 -> 0.98684211
A17: 13 | B17: gid=2143480939 | C17: Mgtr. Pablo Ñauta | D17: ENTREGADO | E17: ENTREGADO | F17: NO ENTREGADO | G17: S/N | H17: S/N | I17: S/N | J17: S/N | K17: S/N | L17: S/N | M17: S/N | N17: S/N | O17: S/N | P17: S/N | Q17: S/N | R17: S/N | S17: S/N | T17: NO SE APERTURÓ ESTE PERIODO | U17: =Madera!$I$59 -> 0
A18: 14 | B18: gid=2011127621 | C18: Mgtr. Lizett Pesántez | D18: ENTREGADO | E18: ENTREGADO | F18: ENTREGADO | G18: S/N | H18: S/N | I18: X | J18: X | K18: x | L18: x | M18: x | N18: x | O18: X | P18: X | Q18: X | R18: X | S18: X | T18: EVIDENCIAS POR COMPLETAR SEGUNDO SEMESTRE | U18: ='Seguridad y Prevención de riesg'!$I$59 -> 0.60526316
A19: 15 | B19: gid=52390556 | C19: Mgtr. Patricio Seminario | D19: ENTREGADO | E19: ENTREGADO | F19: ENTREGADO | G19: S/N | H19: S/N | I19: X | J19: X | K19: x | L19: x | M19: x | N19: x | O19: X | P19: X | Q19: X | R19: X | S19: X | T19: EVIDENCIAS POR COMPLETAR SEGUNDO SEMESTRE | U19: =Tributación!$I$59 -> 0.94736842
A20: 16 | B20: gid=959466057 | C20: Mgtr. Verónica Segarra | D20: ENTREGADO | E20: ENTREGADO | F20: ENTREGADO | G20: S/N | H20: S/N | I20: X | J20: X | K20: x | L20: x | M20: x | N20: x | O20: X | P20: X | Q20: X | R20: X | S20: X | T20: EVIDENCIAS POR COMPLETAR SEGUNDO SEMESTRE | U20: ='Universitaria Software'!$I$59 -> 0.85526316
A21: 17 | B21: gid=1588052260 | C21: Mgtr. Pablo Narváez | D21: ENTREGADO | E21: NO ENTREGADO | F21: NO ENTREGADO | G21: S/N | H21: S/N | I21: S/N | J21: S/N | K21: S/N | L21: S/N | M21: S/N | N21: S/N | O21: S/N | P21: S/N | Q21: S/N | R21: S/N | S21: S/N | T21: NO SE APERTURÓ ESTE PERIODO | U21: ='Universitaria Industrial'!$I$59 -> 0
A22: 18 | B22: gid=572026007 | C22: Mgtr. Jorge Jetón | D22: ENTREGADO | E22: NO ENTREGADO | F22: NO ENTREGADO | G22: S/N | H22: S/N | I22: S/N | J22: S/N | K22: S/N | L22: S/N | M22: S/N | N22: S/N | O22: S/N | P22: S/N | Q22: S/N | R22: S/N | S22: S/N | T22: NO SE APERTURÓ ESTE PERIODO | U22: 0
A23: 19 | B23: gid=777362237 | C23: Mgtr. Catherine Alvear | D23: ENTREGADO | E23: ENTREGADO | F23: ENTREGADO | G23: S/N | H23: S/N | I23: X | J23: X | K23: x | L23: x | M23: x | N23: x | O23: X | P23: X | Q23: X | R23: X | S23: X | T23: EVIDENCIAS POR COMPLETAR SEGUNDO SEMESTRE | U23: ='Educación Inicial'!$I$59 -> 0.93571429

Sheet Entrenamiento Deportivo
C2: Resumen!A1
B4: Plantilla de Gestión por Resultados de la Carrera de Entrenamiento Deportivo con equivalente a Tecnología Superior
C8: Actividades | H8: Producto finales | J8: Costo/Horas
B9: Estado | C9: Prioridad | D9: Fecha de entrega | E9: Tarea | F9: Docente Responsable | G9: Descripción | H9: Entregable | I9: % Ejecutado | J9: Costos fijos | K9: Horas estimadas | L9: Horas actuales | M9: Observación
B10: ESTRATEGIA 1 | E10: OBJETIVO OPERATIVO 1
B11: =FALSE() -> FALSE | C11: Media | D11: 2025-I ( Inicio ciclo) | E11: Planificar y estructurar las capacitaciones en el área técnica y didáctica. | F11: Director/a carrera Docentes | G11: Desarrollo del plan de capacitación docente | H11: Plan de capacitación docente. | I11: 1 | J11: 0 | T11: Alta
B12: =FALSE() -> FALSE | C12: Baja | D12: 2025-I ( fin ciclo) 2025-II ( fin ciclo) | E12: Ejecutar las capacitaciones planificadas. | F12: Director/a carrera Docentes | G12: informar sobre el plan de capacitación docente | H12: Informe de ejecución del plan de capacitación docente. | I12: 1 | J12: 0 | T12: Media
B13: =FALSE() -> FALSE | C13: Media | D13: 2025-I ( fin ciclo) 2025-II ( fin ciclo) | E13: Entregar los resultados de los procesos de Evaluación al desempeño Docente y acciones realizadas. | F13: Director/a carrera Docentes | G13: Generar una matriz para el registro de entrega de evaluaciones docentes | H13: Registro de entrega de evaluaciones a los docentes | I13: 1 | J13: 0 | T13: Baja
E14: OBJETIVO OPERATIVO 2
B15: =FALSE() -> FALSE | C15: Baja | D15: 2025-I ( fin ciclo) 2025-II ( fin ciclo) | E15: Socializar con los docentes el uso adecuado de la plataforma Moodle. | F15: Responsable de Moodle de la carrera | G15: Realizar la socialización y generar un informe sobre el uso del Moodle | H15: Informe de socialización / inducción a los docentes | I15: 1 | J15: 0
B16: =FALSE() -> FALSE | C16: Media | D16: 2025-I ( fin ciclo) 2025-II ( fin ciclo) | E16: Revisar el aporte de cada docente en la plataforma Moodle | F16: Responsable de Moodle de la carrera | G16: Controlar el uso adecuado de la plataforma y generar un informe. | H16: Informe de actividades en la plataforma Moodle. | I16: 1 | J16: 0
E17: OBJETIVO OPERATIVO 3
B18: =FALSE() -> FALSE | C18: Alta | D18: 2025-I ( fin ciclo) 2025-II ( fin ciclo) | E18: Planificar y desarrollar una reunión del colectivo académico | F18: Director/a carrera | G18: Realizar y evidenciar los colectivos académicos | H18: Convocatoria al colectivo de académico | I18: 1 | J18: 0
B19: =FALSE() -> FALSE | C19: Media | D19: 2025-I ( fin ciclo) 2025-II ( fin ciclo) | E19: Revisión y actualización de los PEAS | F19: Director/a carrera Docentes | G19: Revisar si la bibliografía de la carrera es la adecuada en colectivos según PEAS y Colectivos para el acervo bibliográfico | H19: Acervo bibliográfico de todas las asignaturas de la carrera, Informes de colectivos y PEAS revisados | I19: 1 | J19: 0
B20: =FALSE() -> FALSE | C20: Media | D20: 2025-I ( fin ciclo) 2025-II ( fin ciclo) | E20: Actas de reunión por colectivo académico | F20: Director/a carrera Docentes | G20: Evidenciar el trabajo de colectivos | H20: Actas de colectivos | I20: 1 | J20: 0
E21: OBJETIVO OPERATIVO 4
B22: =FALSE() -> FALSE | C22: Baja | D22: 2025-I ( fin ciclo) 2025-II ( fin ciclo) | E22: Recopilar las fichas de afinidad de los docentes de acuerdo al nivel de estudio. | F22: Director/a carrera | G22: Mantener actualizadas las fichas de afinidad de los docentes de acuerdo a la pertinencia en la carrera | H22: Fichas de afinidad de los docentes. | I22: 1 | J22: 0
C23: Alta | D23: 2025-I ( fin ciclo) 2025-II ( fin ciclo) | E23: Elaboración del distributivo docente de la carrera | F23: Director/a carrera | G23: Evidenciar la carga horaria y distributivos de los docentes | H23: Distributivo docente aprobado. | I23: 1 | J23: 0
B24: =FALSE() -> FALSE | C24: Media | D24: 2025-I ( fin ciclo) 2025-II ( fin ciclo) | E24: Designar responsables de la administración de la plataforma, tutorías , prácticas, vinculación , etc. | F24: Director/a carrera | G24: Realizar las designaciones y evidenciar los responsables y tutores de la carrera | H24: Oficios de designaciones de responsables. | I24: 1 | J24: 0
B25: ESTRATEGIA 2 | E25: OBJETIVO OPERATIVO 1
B26: =FALSE() -> FALSE | C26: Alta | D26: 2025-I ( fin ciclo) 2025-II ( fin ciclo) | E26: Elaborar y presentar el calendario de actividades de la o las carreras, horarios de clases y laboratorios. | F26: Director/a carrera | G26: Realizar los documentos necesarios para el desarrollo de las actividades de cada periodo de la carrera | H26: Calendario y horarios aprobados | I26: 1 | J26: 0
B27: =FALSE() -> FALSE | C27: Media | D27: 2025-I ( fin ciclo) 2025-II ( fin ciclo) | E27: Requerimiento y aprobación de Documentos académicos. (Sílabos, guías practicas e informes de avance de Silabo) | F27: Director/a carrera - gestor académico | G27: Solicitud de documentos académicos por materias | H27: Documentación aprobada. | I27: 1 | J27: 0
B28: =FALSE() -> FALSE | C28: Media | D28: 2025-I ( fin ciclo) 2025-II ( fin ciclo) | E28: Seguimiento al cumplimiento de la documentación académica. | F28: Director/a carrera - gestor académico | G28: Revisión de documentos académicos por materias | H28: Informe de carrera sobre la documentación recibida. | I28: 1 | J28: 0
B29: =FALSE() -> FALSE | C29: Baja | D29: 2025-I ( fin ciclo) 2025-II ( fin ciclo) | E29: Reuniones de carrera para socialización y toma de decisiones | F29: Director/a carrera - gestor académico | G29: Reuniones de carrera de acuerdo a requerimientos | H29: Convocatorias, actas e informes de reuniones de carrera. | I29: 1 | J29: 0
B30: =FALSE() -> FALSE | C30: Baja | D30: 45838 | E30: Informe semestral POA 2025 | F30: Director/a carrera - gestor académico | G30: Informar sobre el avance del POA | H30: Informe semestral seguimiento POA 2025 | I30: 1 | J30: 0
B31: =FALSE() -> FALSE | C31: Baja | D31: 45991 | E31: Informe final POA 2025 | F31: Director/a carrera - gestor académico | G31: Informar sobre el alcance final del POA | H31: Informe final POA 2025 | I31: 1 | J31: 0
B32: =FALSE() -> FALSE | C32: Baja | D32: 46011 | E32: Elaborar la Planificación Operativa Anual 2025 | F32: Director/a carrera - gestor académico | G32: Realizar la planificación para el 2026 | H32: POA 2026 | I32: 1 | J32: 0
B33: =FALSE() -> FALSE | C33: Media | D33: 2025-I ( fin ciclo) 2025-II ( fin ciclo) | E33: Designación de tutores de curso | F33: Director/a carrera | G33: Realizar las designaciones y evidenciar los responsables y tutores de la carrera | H33: Documento de designación de tutores por parte del director de carrera | I33: 1 | J33: 0
B34: =FALSE() -> FALSE | C34: Media | D34: 2025-I ( fin ciclo) 2025-II ( fin ciclo) | E34: Ejecutar las actividades de la fase de SEGUIMIENTO del modelo metodológico del proceso de Seguimiento Curricular | F34: Director/a de carrera - Gestor/a académico Tutores de curso | G34: Realizar el Seguimiento del modelo metodológico | H34: Fase SEGUIMIENTO: INICIO: Socialización de Tutorías Académicas DURANTE: Registro de Calificaciones del Primer Parcial FINAL : Registro de Calificación Finales | I34: 1 | J34: 0
B35: =FALSE() -> FALSE | C35: Media | D35: 2025-I ( fin ciclo) 2025-II ( fin ciclo) | E35: Ejecutar las actividades de la fase de CONTROL del modelo metodológico del proceso de Seguimiento Curricular | F35: Director/a de carrera - Gestor/a académico Tutores de curso | G35: Realizar el Control del modelo metodológico | H35: Fase CONTROL: INICIO: Matriz consolidada de resultados de Pruebas de Diagnostico DURANTE: Matriz consolidada de resultados de Calificaciones del Primer Parcial FINAL : Matriz consolidada de resultados de Calificaciones Finales | I35: 1 | J35: 0
B36: =FALSE() -> FALSE | C36: Media | D36: 2025-I(Todo el ciclo) 2025-II(Todo el ciclo) | E36: Ejecutar las actividades de la fase de EVALUACIÓN del modelo metodológico del proceso de Seguimiento Curricular | F36: Director/a de carrera - Gestor/a académico Tutores de curso | G36: Realizar la Evaluación del modelo metodológico | H36: Fase EVALUACIÓN: INICIO: Acta de reunión de inicio de ciclo estudiantes DURANTE: Acta de reunión del Primer Parcial Docentes - Estudiantes FINAL : Acta de reunión Final - Docentes - Estudiantes | I36: 1 | J36: 0
B37: =FALSE() -> FALSE | C37: Baja | D37: 2025-I ( fin ciclo) 2025-II ( fin ciclo) | E37: Elaboración del Plan de Mejoramiento del proceso enseñanza aprendizaje | F37: Director/a carrera Responsable de Seguimiento a graduados de la carrera | G37: De acuerdo a los resultados generar el Plan de Mejoramiento enseñanza aprendizaje | H37: Informe de plan de mejoramiento curricular | I37: 0 | J37: 0 | M37: NO ENTREGADO
E38: OBJETIVO OPERATIVO 2
B39: =TRUE() -> TRUE | C39: Media | D39: 2025-I ( fin ciclo) 2025-II ( fin ciclo) | E39: Diseñar, gestionar e implementar cursos o programas de inducción y de actualización para docentes y estudiantes. | F39: Director/a carrera - gestor académico | G39: Generar la capacitación docente | H39: Informes de cursos y o programas. | I39: 0 | J39: 0 | M39: NO ENTREGADO
B40: =TRUE() -> TRUE | C40: Media | D40: 2025-I ( fin ciclo) 2025-II ( fin ciclo) | E40: Capacitar a los estudiantes sobre la utilización de la Plataforma Moodle. | F40: responsable plataforma Moodle de la carrera | G40: Generar la capacitación estudiantil sobre el Moodle | H40: Informe sobre la capacitación | I40: 0 | J40: 0 | M40: NO ENTREGADO
B41: =TRUE() -> TRUE | C41: Baja | D41: 2025-I ( fin ciclo) 2025-II ( fin ciclo) | E41: Elaborar y ejecutar la planificación de oferta complementaria. | F41: Docentes de la carrera | G41: Analizar y realizar la oferta complementaria | H41: Informe de ejecución de la oferta complementaria. | I41: 0 | J41: 0 | M41: NO ENTREGADO
E42: OBJETIVO OPERATIVO 3
B43: =TRUE() -> TRUE | C43: Alta | D43: 2025-I(Inicio de ciclo) | E43: Revisión de requisitos de la opción de titulación de los estudiantes. | F43: Director de carrera / Coordinador de carreras | G43: Realizar el análisis de la opción de titulación para los estudiantes | H43: Recopilar los documentos de los estudiantes de titulación. | I43: 1 | J43: 0
B44: =TRUE() -> TRUE | C44: Alta | D44: 2025-I(Inicio de ciclo) | E44: Coordinación para aprobación de documentación de la integración curricular. | F44: Director de carrera / Coordinador de carreras | G44: Revisar y coordinar la aprobación de documentos para el ingreso a la unidad de integración curricular | H44: Aprobación de la documentación a titulación. | I44: 1 | J44: 0
B45: =TRUE() -> TRUE | C45: Alta | D45: 2025-I(Fin de ciclo) | E45: Coordinación del evento de incorporación. | F45: Director de carrera / Coordinador de carreras | G45: Realizar la lista de estudiantes a titularse | H45: Matriz de datos de estudiantes a titularse | I45: 1 | J45: 0
...

Sheet Penitenciaria
C2: Resumen!A1
B4: Plantilla de Gestión por Resultados de la Carrera de Seguridad Penitenciaria
C8: Actividades | H8: Producto finales | J8: Costo/Horas
B9: Estado | C9: Prioridad | D9: Fecha de entrega | E9: Tarea | F9: Docente Responsable | H9: Entregable | I9: % Ejecutado | J9: Costos fijos | K9: Horas estimadas | L9: Horas actuales | M9: Observación
B10: ESTRATEGIA 1 | E10: OBJETIVO OPERATIVO 1
B11: =FALSE() -> FALSE | C11: Media | D11: 45690 | E11: Planificar y estructurar las capacitaciones en el área técnica y didáctica. | F11: Director/a carrera Docentes | G11: Desarrollo del plan de capacitación docente | H11: Plan de capacitación docente. | I11: 1 | J11: 0 | T11: Alta
B12: =FALSE() -> FALSE | C12: Baja | D12: 2025-I (Inicio de ciclo) | E12: Ejecutar las capacitaciones planificadas. | F12: Director/a carrera Docentes | G12: informar sobre el plan de capacitación docente | H12: Informe de ejecución del plan de capacitación docente. | I12: 1 | J12: 0 | T12: Media
B13: =FALSE() -> FALSE | C13: Media | D13: 2024-II( intermedio ciclo) 2025-I( fin ciclo) | E13: Entregar los resultados de los procesos de Evaluación al desempeño Docente y acciones realizadas. | F13: Director/a carrera Docentes | G13: Generar una matriz para el registro de entrega de evaluaciones docentes | H13: Registro de entrega de evaluaciones a los docentes | I13: 1 | J13: 0 | T13: Baja
E14: OBJETIVO OPERATIVO 2
B15: =FALSE() -> FALSE | C15: Baja | D15: 2025-I(inicio ciclo) 2025-II(inicio ciclo) | E15: Socializar con los docentes el uso adecuado de la plataforma Moodle. | F15: Responsable de Moodle de la carrera | G15: Realizar la socialización y generar un informe sobre el uso del Moodle | H15: Informe de socialización / inducción a los docentes | I15: 1 | J15: 0
B16: =FALSE() -> FALSE | C16: Media | D16: 2024-II( fin ciclo) 2025-I( fin ciclo) | E16: Revisar el aporte de cada docente en la plataforma Moodle | F16: Responsable de Moodle de la carrera | G16: Controlar el uso adecuado de la plataforma y generar un informe. | H16: Informe de actividades en la plataforma Moodle. | I16: 1 | J16: 0
E17: OBJETIVO OPERATIVO 3
B18: =FALSE() -> FALSE | C18: Alta | D18: 2025-I(inicio ciclo) 2025-II(inicio ciclo) | E18: Planificar y desarrollar una reunión del colectivo académico | F18: Director/a carrera | G18: Realizar y evidenciar los colectivos académicos | H18: Convocatoria al colectivo de académico | I18: 1 | J18: 0
B19: =FALSE() -> FALSE | C19: Media | D19: 2025-I(inicio ciclo) 2025-II(inicio ciclo) | E19: Revisión y actualización de los PEAS | F19: Director/a carrera Docentes | G19: Revisar si la bibliografía de la carrera es la adecuada en colectivos según PEAS y Colectivos para el acervo bibliográfico | H19: Acervo bibliográfico de todas las asignaturas de la carrera, Informes de colectivos y PEAS revisados | I19: 1 | J19: 0 | M19: Los PEAS están en la carpeta de la ESTRATEGIA 2 - OBJETIVO 1
B20: =FALSE() -> FALSE | C20: Media | D20: 2024-II(fin de ciclo) | E20: Actas de reunión por colectivo académico | F20: Director/a carrera Docentes | G20: Evidenciar el trabajo de colectivos | H20: Actas de colectivos | I20: 1 | J20: 0
E21: OBJETIVO OPERATIVO 4
B22: =FALSE() -> FALSE | C22: Baja | D22: 2025-I(inicio ciclo) 2025-II (inicio ciclo) | E22: Recopilar las fichas de afinidad de los docentes de acuerdo al nivel de estudio. | F22: Director/a carrera | G22: Mantener actualizadas las fichas de afinidad de los docentes de acuerdo a la pertinencia en la carrera | H22: Fichas de afinidad de los docentes. | I22: 1 | J22: 0
C23: Alta | D23: 2025-I(inicio de ciclo) 2025-II(inicio de ciclo) | E23: Elaboración del distributivo docente de la carrera | F23: Director/a carrera | G23: Evidenciar la carga horaria y distributivos de los docentes | H23: Distributivo docente aprobado. | I23: 1 | J23: 0
B24: =FALSE() -> FALSE | C24: Media | D24: 2025-I(inicio de ciclo) 2025-II(inicio de ciclo) | E24: Designar responsables de la administración de la plataforma, tutorías , prácticas, vinculación , etc. | F24: Director/a carrera | G24: Realizar las designaciones y evidenciar los responsables y tutores de la carrera | H24: Oficios de designaciones de responsables. | I24: 1 | J24: 0
B25: ESTRATEGIA 2 | E25: OBJETIVO OPERATIVO 1
B26: =FALSE() -> FALSE | C26: Alta | D26: 2025-I(Inicio de ciclo) 2025-II(Inicio de ciclo) | E26: Elaborar y presentar el calendario de actividades de la o las carreras, horarios de clases y laboratorios. | F26: Director/a carrera | G26: Realizar los documentos necesarios para el desarrollo de las actividades de cada periodo de la carrera | H26: Calendario y horarios aprobados | I26: 1 | J26: 0
B27: =FALSE() -> FALSE | C27: Media | D27: 2025-I(Todo de ciclo) | E27: Requerimiento y aprobación de Documentos académicos. (Sílabos, guías practicas e informes de avance de Silabo) | F27: Director/a carrera - gestor académico | G27: Solicitud de documentos académicos por materias | H27: Documentación aprobada. | I27: 0.22 | J27: 0 | M27: NO constan las guías prácticas, ni tampoco los avances de Sílabo.
B28: =FALSE() -> FALSE | C28: Media | D28: 2025-I(Todo el ciclo) 2025-II(Todo de ciclo) | E28: Seguimiento al cumplimiento de la documentación académica. | F28: Director/a carrera - gestor académico | G28: Revisión de documentos académicos por materias | H28: Informe de carrera sobre la documentación recibida. | I28: 0 | J28: 0 | M28: NO constan los informes sobre la documentación recibida.
B29: =FALSE() -> FALSE | C29: Baja | D29: 2025-I(Todo el ciclo) 2025-II(Todo de ciclo) | E29: Reuniones de carrera para socialización y toma de decisiones | F29: Director/a carrera - gestor académico | G29: Reuniones de carrera de acuerdo a requerimientos | H29: Convocatorias, actas e informes de reuniones de carrera. | I29: 1 | J29: 0
B30: =FALSE() -> FALSE | C30: Baja | D30: 45838 | E30: Informe semestral POA 2025 | F30: Director/a carrera - gestor académico | G30: Informar sobre el avance del POA | H30: Informe semestral seguimiento POA 2025 | I30: 1 | J30: 0
B31: =FALSE() -> FALSE | C31: Baja | D31: 45991 | E31: Informe final POA 2026 | F31: Director/a carrera - gestor académico | G31: Informar sobre el alcance final del POA | H31: Informe final POA 2025 | I31: 1 | J31: 0
B32: =FALSE() -> FALSE | C32: Baja | D32: 46011 | E32: Elaborar la Planificación Operativa Anual 2026 | F32: Director/a carrera - gestor académico | G32: Realizar la planificación para el 2025 | H32: POA 2026 entregado | I32: 1 | J32: 0
B33: =FALSE() -> FALSE | C33: Media | D33: 2025-I (inicio de ciclo) 2025-II (inicio de ciclo) | E33: Designación de tutores de curso | F33: Director/a carrera | G33: Realizar las designaciones y evidenciar los responsables y tutores de la carrera | H33: Documento de designación de tutores por parte del director de carrera | I33: 1 | J33: 0
B34: =FALSE() -> FALSE | C34: Media | D34: 2025-I(Todo el ciclo) 2025-II(Todo el ciclo) | E34: Ejecutar las actividades de la fase de SEGUIMIENTO del modelo metodológico del proceso de Seguimiento Curricular | F34: Director/a de carrera - Gestor/a académico Tutores de curso | G34: Realizar el Seguimiento del modelo metodológico | H34: Fase SEGUIMIENTO: INICIO: Socialización de Tutorías Académicas DURANTE: Registro de Calificaciones del Primer Parcial FINAL : Registro de Calificación Finales | I34: 1 | J34: 0
B35: =FALSE() -> FALSE | C35: Media | D35: 2025-I(Todo el ciclo) 2025-II(Todo el ciclo) | E35: Ejecutar las actividades de la fase de CONTROL del modelo metodológico del proceso de Seguimiento Curricular | F35: Director/a de carrera - Gestor/a académico Tutores de curso | G35: Realizar el Control del modelo metodológico | H35: Fase CONTROL: INICIO: Matriz consolidada de resultados de Pruebas de Diagnostico DURANTE: Matriz consolidada de resultados de Calificaciones del Primer Parcial FINAL : Matriz consolidada de resultados de Calificaciones Finales | I35: 0.5 | J35: 0 | M35: NO consta la matriz consolidada del ciclo aacadémico 2025-II
B36: =FALSE() -> FALSE | C36: Media | D36: 2024-II(Todo el ciclo) 2025-I(Todo el ciclo) | E36: Ejecutar las actividades de la fase de EVALUACIÓN del modelo metodológico del proceso de Seguimiento Curricular | F36: Director/a de carrera - Gestor/a académico Tutores de curso | G36: Realizar la Evaluación del modelo metodológico | H36: Fase EVALAUCIÓN: INICIO: Acta de reunión de inicio de ciclo estudiantes DURANTE: Acta de reunión del Primer Parcial Docentes - Estudiantes FINAL : Acta de reunión Final - Docentes - Estudiantes | I36: 0.5 | J36: 0 | M36: NO consta el acta de reuniones del primer ciclo, ni tampoco la del primer parcial del ciclo aacadémico 2025-II
B37: =FALSE() -> FALSE | C37: Baja | D37: 2025-II (Fin de Ciclo) | E37: Elaboración del Plan de Mejoramiento del proceso enseñanza aprendizaje | F37: Director/a carrera Responsable de Seguimiento a graduados de la carrera | G37: De acuerdo a los resultados generar el Plan de Mejoramiento enseñanza aprendizaje | H37: Informe de plan de mejoramiento curricular | I37: 0 | J37: 0 | M37: NO consta el Plan de mejoramiento curricular del ciclo 2025-I
E38: OBJETIVO OPERATIVO 2
B39: =TRUE() -> TRUE | C39: Media | D39: 2025-II(Inicio de ciclo) | E39: Diseñar, gestionar e implementar cursos o programas de inducción y de actualización para docentes y estudiantes. | F39: Director/a carrera - gestor académico | G39: Generar la capacitación docente | H39: Informes de cursos y o programas. | I39: 0.5 | J39: 0 | M39: NO consta el informe de cursos y/o programas del ciclo académico 2025-II
B40: =TRUE() -> TRUE | C40: Media | D40: 2025-I(Todo el ciclo) 2025-II(Todo el ciclo) | E40: Capacitar a los estudiantes sobre la utilización de la Plataforma Moodle. | F40: responsable plataforma Moodle de la carrera | G40: Generar la capacitación estudiantil sobre el Moodle | H40: Informe sobre la capacitación | I40: 1 | J40: 0
B41: =TRUE() -> TRUE | C41: Baja | D41: 2025-II(Fin de ciclo) | E41: Elaborar y ejecutar la planificación de oferta complementaria. | F41: Docentes de la carrera | G41: Analizar y realizar la oferta complementaria | H41: Informe de ejecución de la oferta complementaria. | I41: 0 | J41: 0 | M41: NO consta el informe
E42: OBJETIVO OPERATIVO 3
B43: =TRUE() -> TRUE | C43: Alta | D43: 45693 | E43: Revisión de requisitos de la opción de titulación de los estudiantes. | F43: Director de carrera / Coordinador de carreras | G43: Realizar el análisis de la opción de titulación para los estudiantes | H43: Recopilar los documentos de los estudiantes de titulación. | I43: 1 | J43: 0
B44: =TRUE() -> TRUE | C44: Alta | D44: 45722 | E44: Coordinación para aprobación de documentación de la integración curricular. | F44: Director de carrera / Coordinador de carreras | G44: Revisar y coordinar la aprobación de documentos para el ingreso a la unidad de integración curricular | H44: Aprobación de la documentación a titulación. | I44: 1 | J44: 0
B45: =TRUE() -> TRUE | C45: Alta | D45: 45780 | E45: Coordinación del evento de incorporación. | F45: Director de carrera / Coordinador de carreras | G45: Realizar la lista de estudiantes a titularse | H45: Matriz de datos de estudiantes a titularse | I45: 1 | J45: 0
...

Sheet Producción Audiovisual
B2: Resumen!A1
B4: Plantilla de Gestión por Resultados de la Carrera Tecnología Superior en Producción y Realización Audiovisual
C8: Actividades | H8: Producto finales | J8: Costo/Horas
B9: Estado | C9: Prioridad | D9: Fecha de entrega | E9: Tarea | F9: Docente Responsable | G9: Descripción | H9: Entregable | I9: % Ejecutado | J9: Costos fijos | K9: Horas estimadas | L9: Horas actuales | M9: Observación
B10: ESTRATEGIA 1 | E10: OBJETIVO OPERATIVO 1
B11: =FALSE() -> FALSE | C11: Media | D11: 2025-I ( Inicio ciclo) | E11: Planificar y estructurar las capacitaciones en el área técnica y didáctica. | F11: Director/a carrera Docentes | G11: Desarrollo del plan de capacitación docente | H11: Plan de capacitación docente. | I11: 1 | J11: 0 | T11: Alta
B12: =FALSE() -> FALSE | C12: Baja | D12: 2025-II ( fin ciclo) | E12: Ejecutar las capacitaciones planificadas. | F12: Director/a carrera Docentes | G12: informar sobre el plan de capacitación docente | H12: Informe de ejecución del plan de capacitación docente. | I12: 0.5 | J12: 0 | M12: NO consta el informe de ejecución del plan de capacitación docente del ciclo 2025-II. | T12: Media
B13: =FALSE() -> FALSE | C13: Media | D13: 2025-II( fin ciclo) 2025-I( fin ciclo) | E13: Entregar los resultados de los procesos de Evaluación al desempeño Docente y acciones realizadas. | F13: Director/a carrera Docentes | G13: Generar una matriz para el registro de entrega de evaluaciones docentes | H13: Registro de entrega de evaluaciones a los docentes | I13: 0.5 | J13: 0 | M13: NO consta el registro de entrega de evaluaciones del ciclo 2025-II. | T13: Baja
E14: OBJETIVO OPERATIVO 2
B15: =FALSE() -> FALSE | C15: Baja | D15: 2025-I (inicio ciclo) 2025-II(inicio ciclo) | E15: Socializar con los docentes el uso adecuado de la plataforma Moodle. | F15: Responsable de Moodle de la carrera | G15: Realizar la socialización y generar un informe sobre el uso del Moodle | H15: Informe de socialización / inducción a los docentes | I15: 0.5 | J15: 0 | M15: NO consta el informe de socialización del ciclo 2025-II.
B16: =FALSE() -> FALSE | C16: Media | D16: 2025-II( fin ciclo) 2025-I( fin ciclo) | E16: Revisar el aporte de cada docente en la plataforma Moodle | F16: Responsable de Moodle de la carrera | G16: Controlar el uso adecuado de la plataforma y generar un informe. | H16: Informe de actividades en la plataforma Moodle. | I16: 0.5 | J16: 0 | M16: NO consta el informe de actividades del ciclo 2025-II.
E17: OBJETIVO OPERATIVO 3
B18: =FALSE() -> FALSE | C18: Alta | D18: 2025-I(inicio ciclo) 2025-II (inicio ciclo) | E18: Planificar y desarrollar una reunión del colectivo académico | F18: Director/a carrera | G18: Realizar y evidenciar los colectivos académicos | H18: Convocatoria al colectivo de académico | I18: 0 | J18: 0 | M18: Debe subirse una sola vez cuando es rediseño, NO hay evidencia.
B19: =FALSE() -> FALSE | C19: Media | D19: 2025-II(fin de ciclo) 2025-I(fin de ciclo) | E19: Revisión y actualización de los PEAS | F19: Director/a carrera Docentes | G19: Revisar si la bibliografía de la carrera es la adecuada en colectivos según PEAS y Colectivos para el acervo bibliográfico | H19: Acervo bibliográfico de todas las asignaturas de la carrera, Informes de colectivos y PEAS revisados | I19: 0.5 | J19: 0 | M19: NO consta el acervo bibliográfico del ciclo académico 2025-II
B20: =FALSE() -> FALSE | C20: Media | D20: 2025-II(fin de ciclo) 2025-I(fin de ciclo) | E20: Actas de reunión por colectivo académico | F20: Director/a carrera Docentes | G20: Evidenciar el trabajo de colectivos | H20: Actas de colectivos | I20: 0 | J20: 0 | M20: NO constan las actas de la reunión con los colectivos.
E21: OBJETIVO OPERATIVO 4
B22: =FALSE() -> FALSE | C22: Baja | D22: 2025-I(inicio ciclo) 2025-II (inicio ciclo) | E22: Recopilar las fichas de afinidad de los docentes de acuerdo al nivel de estudio. | F22: Director/a carrera | G22: Mantener actualizadas las fichas de afinidad de los docentes de acuerdo a la pertinencia en la carrera | H22: Fichas de afinidad de los docentes. | I22: 0.5 | J22: 0 | M22: NO constan las fichas de afinidad del ciclo académico 2025-II.
C23: Alta | D23: 2025-I(inicio de ciclo) 2025-II(inicio de ciclo) | E23: Elaboración del distributivo docente de la carrera | F23: Director/a carrera | G23: Evidenciar la carga horaria y distributivos de los docentes | H23: Distributivo docente aprobado. | I23: 0.5 | J23: 0 | M23: NO constan los distributivos docentes del ciclo académico 2025-II
B24: =FALSE() -> FALSE | C24: Media | D24: 2025-I(inicio de ciclo) 2025-II(inicio de ciclo) | E24: Designar responsables de la administración de la plataforma, tutorías , prácticas, vinculación , etc. | F24: Director/a carrera | G24: Realizar las designaciones y evidenciar los responsables y tutores de la carrera | H24: Oficios de designaciones de responsables. | I24: 0.5 | J24: 0 | M24: NO constan los oficios de designaciones del ciclo académico 2025-II
B25: ESTRATEGIA 2 | E25: OBJETIVO OPERATIVO 1
B26: =FALSE() -> FALSE | C26: Alta | D26: 2025-I(Inicio de ciclo) 2025-II(Inicio de ciclo) | E26: Elaborar y presentar el calendario de actividades de la o las carreras, horarios de clases y laboratorios. | F26: Director/a carrera | G26: Realizar los documentos necesarios para el desarrollo de las actividades de cada periodo de la carrera | H26: Calendario y horarios aprobados | I26: 0.5 | J26: 0 | M26: NO constan el calendario y horarios del ciclo académico 2025-II
B27: =FALSE() -> FALSE | C27: Media | D27: 2025-I(Todo el ciclo) 2025-II(Todo de ciclo) | E27: Requerimiento y aprobación de Documentos académicos. (Sílabos, guías practicas e informes de avance de Silabo) | F27: Director/a carrera - gestor académico | G27: Solicitud de documentos académicos por materias | H27: Documentación aprobada. | I27: 0.5 | J27: 0 | M27: NO consta la documentación del ciclo académico 2025-II
B28: =FALSE() -> FALSE | C28: Media | D28: 2025-I(Todo el ciclo) 2025-II(Todo de ciclo) | E28: Seguimiento al cumplimiento de la documentación académica. | F28: Director/a carrera - gestor académico | G28: Revisión de documentos académicos por materias | H28: Informe de carrera sobre la documentación recibida. | I28: 0.5 | J28: 0 | M28: NO consta la documentación del ciclo académico 2025-II
B29: =FALSE() -> FALSE | C29: Baja | D29: 2025-I(Todo el ciclo) 2025-II(Todo de ciclo) | E29: Reuniones de carrera para socialización y toma de decisiones | F29: Director/a carrera - gestor académico | G29: Reuniones de carrera de acuerdo a requerimientos | H29: Convocatorias, actas e informes de reuniones de carrera. | I29: 0.5 | J29: 0 | M29: NO consta la documentación del ciclo académico 2025-II
B30: =FALSE() -> FALSE | C30: Baja | D30: 45838 | E30: Informe semestral POA 2025 | F30: Director/a carrera - gestor académico | G30: Informar sobre el avance del POA | H30: Informe semestral seguimiento POA 2025 | I30: 1 | J30: 0
B31: =FALSE() -> FALSE | C31: Baja | D31: 45991 | E31: Informe final POA 2025 | F31: Director/a carrera - gestor académico | G31: Informar sobre el alcance final del POA | H31: Informe final POA 2025 | I31: 1 | J31: 0
B32: =FALSE() -> FALSE | C32: Baja | D32: 46011 | E32: Elaborar la Planificación Operativa Anual 2025 | F32: Director/a carrera - gestor académico | G32: Realizar la planificación para el 2026 | H32: POA 2026 | I32: 1 | J32: 0
B33: =FALSE() -> FALSE | C33: Media | D33: 2025-I (inicio de ciclo) 2025-II (inicio de ciclo) | E33: Designación de tutores de curso | F33: Director/a carrera | G33: Realizar las designaciones y evidenciar los responsables y tutores de la carrera | H33: Documento de designación de tutores por parte del director de carrera | I33: 0.5 | J33: 0 | M33: NO consta la documentación del ciclo académico 2025-II
B34: =FALSE() -> FALSE | C34: Media | D34: 2025-I(Todo el ciclo) 2025-II(Todo el ciclo) | E34: Ejecutar las actividades de la fase de SEGUIMIENTO del modelo metodológico del proceso de Seguimiento Curricular | F34: Director/a de carrera - Gestor/a académico Tutores de curso | G34: Realizar el Seguimiento del modelo metodológico | H34: Fase SEGUIMIENTO: INICIO: Socialización de Tutorías Académicas DURANTE: Registro de Calificaciones del Primer Parcial FINAL : Registro de Calificación Finales | I34: 0.5 | J34: 0 | M34: NO consta la documentación del ciclo académico 2025-II
B35: =FALSE() -> FALSE | C35: Media | D35: 2025-I(Todo el ciclo) 2025-II(Todo el ciclo) | E35: Ejecutar las actividades de la fase de CONTROL del modelo metodológico del proceso de Seguimiento Curricular | F35: Director/a de carrera - Gestor/a académico Tutores de curso | G35: Realizar el Control del modelo metodológico | H35: Fase CONTROL: INICIO: Matriz consolidada de resultados de Pruebas de Diagnostico DURANTE: Matriz consolidada de resultados de Calificaciones del Primer Parcial FINAL : Matriz consolidada de resultados de Calificaciones Finales | I35: 0.5 | J35: 0 | M35: NO consta la documentación del ciclo académico 2025-II
B36: =FALSE() -> FALSE | C36: Media | D36: 2025-I(Todo el ciclo) 2025-II(Todo el ciclo) | E36: Ejecutar las actividades de la fase de EVALUACIÓN del modelo metodológico del proceso de Seguimiento Curricular | F36: Director/a de carrera - Gestor/a académico Tutores de curso | G36: Realizar la Evaluación del modelo metodológico | H36: Fase EVALAUCIÓN: INICIO: Acta de reunión de inicio de ciclo estudiantes DURANTE: Acta de reunión del Primer Parcial Docentes - Estudiantes FINAL : Acta de reunión Final - Docentes - Estudiantes | I36: 0.5 | J36: 0 | M36: NO consta la documentación del ciclo académico 2025-II
B37: =FALSE() -> FALSE | C37: Baja | D37: 2025-II(Fin de ciclo) 2025-I(Fin de Ciclo) | E37: Elaboración del Plan de Mejoramiento del proceso enseñanza aprendizaje | F37: Director/a carrera Responsable de Seguimiento a graduados de la carrera | G37: De acuerdo a los resultados generar el Plan de Mejoramiento enseñanza aprendizaje | H37: Informe de plan de mejoramiento curricular | I37: 0.5 | J37: 0 | M37: NO consta el informe de plan de mejoramiento curricular del ciclo 2025-I
E38: OBJETIVO OPERATIVO 2
B39: =TRUE() -> TRUE | C39: Media | D39: 2025-II(Inicio de ciclo) | E39: Diseñar, gestionar e implementar cursos o programas de inducción y de actualización para docentes y estudiantes. | F39: Director/a carrera - gestor académico | G39: Generar la capacitación docente | H39: Informes de cursos y o programas. | I39: 0.5 | J39: 0 | M39: NO consta el informe de cursos y/o capacitaciones del ciclo 2025-II
B40: =TRUE() -> TRUE | C40: Media | D40: 2025-II(Inicio de ciclo) | E40: Capacitar a los estudiantes sobre la utilización de la Plataforma Moodle. | F40: responsable plataforma Moodle de la carrera | G40: Generar la capacitación estudiantil sobre el Moodle | H40: Informe sobre la capacitación | I40: 0 | J40: 0 | M40: NO se encuentran las evidencias
B41: =TRUE() -> TRUE | C41: Baja | D41: 2025-II(Fin de ciclo) | E41: Elaborar y ejecutar la planificación de oferta complementaria. | F41: Docentes de la carrera | G41: Analizar y realizar la oferta complementaria | H41: Informe de ejecución de la oferta complementaria. | I41: 0 | J41: 0 | M41: NO se encuentran las evidencias
E42: OBJETIVO OPERATIVO 3
B43: =TRUE() -> TRUE | C43: Alta | D43: 2025-I(Inicio de ciclo) | E43: Revisión de requisitos de la opción de titulación de los estudiantes. | F43: Director de carrera / Coordinador de carreras | G43: Realizar el análisis de la opción de titulación para los estudiantes | H43: Recopilar los documentos de los estudiantes de titulación. | I43: 0 | J43: 0 | M43: NO se encuentran las evidencias
B44: =TRUE() -> TRUE | C44: Alta | D44: 2025-I(Inicio de ciclo) | E44: Coordinación para aprobación de documentación de la integración curricular. | F44: Director de carrera / Coordinador de carreras | G44: Revisar y coordinar la aprobación de documentos para el ingreso a la unidad de integración curricular | H44: Aprobación de la documentación a titulación. | I44: 0 | J44: 0 | M44: NO se encuentran las evidencias
B45: =TRUE() -> TRUE | C45: Alta | D45: 2025-I(Fin de ciclo) | E45: Coordinación del evento de incorporación. | F45: Director de carrera / Coordinador de carreras | G45: Realizar la lista de estudiantes a titularse | H45: Matriz de datos de estudiantes a titularse | I45: 0 | J45: 0 | M45: NO se encuentran las evidencias
...

Sheet Plataformas tecnológicas
B2: Resumen!A1
B4: Plantilla de Gestión por Resultados de la Carrera Tecnología Superior en Administración de Infraestructura y Plataformas Tecnologícas
C8: Actividades | H8: Producto finales | J8: Costo/Horas
B9: Estado | C9: Prioridad | D9: Fecha de entrega | E9: Tarea | F9: Docente Responsable | G9: Descripción | H9: Entregable | I9: % Ejecutado | J9: Costos fijos | K9: Horas estimadas | L9: Horas actuales | M9: Observación
B10: ESTRATEGIA 1 | E10: OBJETIVO OPERATIVO 1
B11: =FALSE() -> FALSE | C11: Media | D11: 2025-I ( Inicio ciclo) | E11: Planificar y estructurar las capacitaciones en el área técnica y didáctica. | F11: Director/a carrera Docentes | G11: Desarrollo del plan de capacitación docente | H11: Plan de capacitación docente. | I11: 1 | J11: 0 | T11: Alta
B12: =FALSE() -> FALSE | C12: Baja | D12: 2025-II ( fin ciclo) | E12: Ejecutar las capacitaciones planificadas. | F12: Director/a carrera Docentes | G12: informar sobre el plan de capacitación docente | H12: Informe de ejecución del plan de capacitación docente. | I12: 1 | J12: 0 | T12: Media
B13: =FALSE() -> FALSE | C13: Media | D13: 2025-II( fin ciclo) 2025-I( fin ciclo) | E13: Entregar los resultados de los procesos de Evaluación al desempeño Docente y acciones realizadas. | F13: Director/a carrera Docentes | G13: Generar una matriz para el registro de entrega de evaluaciones docentes | H13: Registro de entrega de evaluaciones a los docentes | I13: 1 | J13: 0 | T13: Baja
E14: OBJETIVO OPERATIVO 2
B15: =FALSE() -> FALSE | C15: Baja | D15: 2025-I (inicio ciclo) 2025-II(inicio ciclo) | E15: Socializar con los docentes el uso adecuado de la plataforma Moodle. | F15: Responsable de Moodle de la carrera | G15: Realizar la socialización y generar un informe sobre el uso del Moodle | H15: Informe de socialización / inducción a los docentes | I15: 1 | J15: 0
B16: =FALSE() -> FALSE | C16: Media | D16: 2025-II( fin ciclo) 2025-I( fin ciclo) | E16: Revisar el aporte de cada docente en la plataforma Moodle | F16: Responsable de Moodle de la carrera | G16: Controlar el uso adecuado de la plataforma y generar un informe. | H16: Informe de actividades en la plataforma Moodle. | I16: 1 | J16: 0
E17: OBJETIVO OPERATIVO 3
B18: =FALSE() -> FALSE | C18: Alta | D18: 2025-I(inicio ciclo) 2025-II (inicio ciclo) | E18: Planificar y desarrollar una reunión del colectivo académico | F18: Director/a carrera | G18: Realizar y evidenciar los colectivos académicos | H18: Convocatoria al colectivo de académico | I18: 1 | J18: 0
B19: =FALSE() -> FALSE | C19: Media | D19: 2025-II(fin de ciclo) 2025-I(fin de ciclo) | E19: Revisión y actualización de los PEAS | F19: Director/a carrera Docentes | G19: Revisar si la bibliografía de la carrera es la adecuada en colectivos según PEAS y Colectivos para el acervo bibliográfico | H19: Acervo bibliográfico de todas las asignaturas de la carrera, Informes de colectivos y PEAS revisados | I19: 1 | J19: 0
B20: =FALSE() -> FALSE | C20: Media | D20: 2025-II(fin de ciclo) 2025-I(fin de ciclo) | E20: Actas de reunión por colectivo académico | F20: Director/a carrera Docentes | G20: Evidenciar el trabajo de colectivos | H20: Actas de colectivos | I20: 1 | J20: 0
E21: OBJETIVO OPERATIVO 4
B22: =FALSE() -> FALSE | C22: Baja | D22: 2025-I(inicio ciclo) 2025-II (inicio ciclo) | E22: Recopilar las fichas de afinidad de los docentes de acuerdo al nivel de estudio. | F22: Director/a carrera | G22: Mantener actualizadas las fichas de afinidad de los docentes de acuerdo a la pertinencia en la carrera | H22: Fichas de afinidad de los docentes. | I22: 1 | J22: 0
C23: Alta | D23: 2025-I(inicio de ciclo) 2025-II(inicio de ciclo) | E23: Elaboración del distributivo docente de la carrera | F23: Director/a carrera | G23: Evidenciar la carga horaria y distributivos de los docentes | H23: Distributivo docente aprobado. | I23: 1 | J23: 0
B24: =FALSE() -> FALSE | C24: Media | D24: 2025-I(inicio de ciclo) 2025-II(inicio de ciclo) | E24: Designar responsables de la administración de la plataforma, tutorías , prácticas, vinculación , etc. | F24: Director/a carrera | G24: Realizar las designaciones y evidenciar los responsables y tutores de la carrera | H24: Oficios de designaciones de responsables. | I24: 1 | J24: 0
B25: ESTRATEGIA 2 | E25: OBJETIVO OPERATIVO 1
B26: =FALSE() -> FALSE | C26: Alta | D26: 2025-I(Inicio de ciclo) 2025-II(Inicio de ciclo) | E26: Elaborar y presentar el calendario de actividades de la o las carreras, horarios de clases y laboratorios. | F26: Director/a carrera | G26: Realizar los documentos necesarios para el desarrollo de las actividades de cada periodo de la carrera | H26: Calendario y horarios aprobados | I26: 1 | J26: 0
B27: =FALSE() -> FALSE | C27: Media | D27: 2025-I(Todo el ciclo) 2025-II(Todo de ciclo) | E27: Requerimiento y aprobación de Documentos académicos. (Sílabos, guías practicas e informes de avance de Silabo) | F27: Director/a carrera - gestor académico | G27: Solicitud de documentos académicos por materias | H27: Documentación aprobada. | I27: 1 | J27: 0
B28: =FALSE() -> FALSE | C28: Media | D28: 2025-I(Todo el ciclo) 2025-II(Todo de ciclo) | E28: Seguimiento al cumplimiento de la documentación académica. | F28: Director/a carrera - gestor académico | G28: Revisión de documentos académicos por materias | H28: Informe de carrera sobre la documentación recibida. | I28: 1 | J28: 0
B29: =FALSE() -> FALSE | C29: Baja | D29: 2025-I(Todo el ciclo) 2025-II(Todo de ciclo) | E29: Reuniones de carrera para socialización y toma de decisiones | F29: Director/a carrera - gestor académico | G29: Reuniones de carrera de acuerdo a requerimientos | H29: Convocatorias, actas e informes de reuniones de carrera. | I29: 1 | J29: 0
B30: =FALSE() -> FALSE | C30: Baja | D30: 45838 | E30: Informe semestral POA 2025 | F30: Director/a carrera - gestor académico | G30: Informar sobre el avance del POA | H30: Informe semestral seguimiento POA 2025 | I30: 1 | J30: 0
B31: =FALSE() -> FALSE | C31: Baja | D31: 45991 | E31: Informe final POA 2025 | F31: Director/a carrera - gestor académico | G31: Informar sobre el alcance final del POA | H31: Informe final POA 2025 | I31: 1 | J31: 0
B32: =FALSE() -> FALSE | C32: Baja | D32: 46011 | E32: Elaborar la Planificación Operativa Anual 2025 | F32: Director/a carrera - gestor académico | G32: Realizar la planificación para el 2026 | H32: POA 2026 | I32: 1 | J32: 0
B33: =FALSE() -> FALSE | C33: Media | D33: 2025-I (inicio de ciclo) 2025-II (inicio de ciclo) | E33: Designación de tutores de curso | F33: Director/a carrera | G33: Realizar las designaciones y evidenciar los responsables y tutores de la carrera | H33: Documento de designación de tutores por parte del director de carrera | I33: 1 | J33: 0
B34: =FALSE() -> FALSE | C34: Media | D34: 2025-I(Todo el ciclo) 2025-II(Todo el ciclo) | E34: Ejecutar las actividades de la fase de SEGUIMIENTO del modelo metodológico del proceso de Seguimiento Curricular | F34: Director/a de carrera - Gestor/a académico Tutores de curso | G34: Realizar el Seguimiento del modelo metodológico | H34: Fase SEGUIMIENTO: INICIO: Socialización de Tutorías Académicas DURANTE: Registro de Calificaciones del Primer Parcial FINAL : Registro de Calificación Finales | I34: 1 | J34: 0
B35: =FALSE() -> FALSE | C35: Media | D35: 2025-I(Todo el ciclo) 2025-II(Todo el ciclo) | E35: Ejecutar las actividades de la fase de CONTROL del modelo metodológico del proceso de Seguimiento Curricular | F35: Director/a de carrera - Gestor/a académico Tutores de curso | G35: Realizar el Control del modelo metodológico | H35: Fase CONTROL: INICIO: Matriz consolidada de resultados de Pruebas de Diagnostico DURANTE: Matriz consolidada de resultados de Calificaciones del Primer Parcial FINAL : Matriz consolidada de resultados de Calificaciones Finales | I35: 1 | J35: 0 | M35: NO existe la Matriz consolidada de resultados de calificaciones del Primer Parcial del Ciclo 2025-II
B36: =FALSE() -> FALSE | C36: Media | D36: 2025-I(Todo el ciclo) 2025-II(Todo el ciclo) | E36: Ejecutar las actividades de la fase de EVALUACIÓN del modelo metodológico del proceso de Seguimiento Curricular | F36: Director/a de carrera - Gestor/a académico Tutores de curso | G36: Realizar la Evaluación del modelo metodológico | H36: Fase EVALAUCIÓN: INICIO: Acta de reunión de inicio de ciclo estudiantes DURANTE: Acta de reunión del Primer Parcial Docentes - Estudiantes FINAL : Acta de reunión Final - Docentes - Estudiantes | I36: 0.67 | J36: 0 | M36: NO existe el acta de reunión del Primer Parcial Docentes-Estudiantes del Ciclo 2025-II
B37: =FALSE() -> FALSE | C37: Baja | D37: 2025-II(Fin de ciclo) 2025-I(Fin de Ciclo) | E37: Elaboración del Plan de Mejoramiento del proceso enseñanza aprendizaje | F37: Director/a carrera Responsable de Seguimiento a graduados de la carrera | G37: De acuerdo a los resultados generar el Plan de Mejoramiento enseñanza aprendizaje | H37: Informe de plan de mejoramiento curricular | I37: 1 | J37: 0
E38: OBJETIVO OPERATIVO 2
B39: =TRUE() -> TRUE | C39: Media | D39: 2025-II(Inicio de ciclo) | E39: Diseñar, gestionar e implementar cursos o programas de inducción y de actualización para docentes y estudiantes. | F39: Director/a carrera - gestor académico | G39: Generar la capacitación docente | H39: Informes de cursos y o programas. | I39: 1 | J39: 0
B40: =TRUE() -> TRUE | C40: Media | D40: 2025-II(Inicio de ciclo) | E40: Capacitar a los estudiantes sobre la utilización de la Plataforma Moodle. | F40: responsable plataforma Moodle de la carrera | G40: Generar la capacitación estudiantil sobre el Moodle | H40: Informe sobre la capacitación | I40: 1 | J40: 0
B41: =TRUE() -> TRUE | C41: Baja | D41: 2025-II(Fin de ciclo) | E41: Elaborar y ejecutar la planificación de oferta complementaria. | F41: Docentes de la carrera | G41: Analizar y realizar la oferta complementaria | H41: Informe de ejecución de la oferta complementaria. | I41: 1 | J41: 0
E42: OBJETIVO OPERATIVO 3
B43: =TRUE() -> TRUE | C43: Alta | D43: 2025-I(Inicio de ciclo) | E43: Revisión de requisitos de la opción de titulación de los estudiantes. | F43: Director de carrera / Coordinador de carreras | G43: Realizar el análisis de la opción de titulación para los estudiantes | H43: Recopilar los documentos de los estudiantes de titulación. | I43: 1 | J43: 0
B44: =TRUE() -> TRUE | C44: Alta | D44: 2025-I(Inicio de ciclo) | E44: Coordinación para aprobación de documentación de la integración curricular. | F44: Director de carrera / Coordinador de carreras | G44: Revisar y coordinar la aprobación de documentos para el ingreso a la unidad de integración curricular | H44: Aprobación de la documentación a titulación. | I44: 1 | J44: 0
B45: =TRUE() -> TRUE | C45: Alta | D45: 2025-I(Fin de ciclo) | E45: Coordinación del evento de incorporación. | F45: Director de carrera / Coordinador de carreras | G45: Realizar la lista de estudiantes a titularse | H45: Matriz de datos de estudiantes a titularse | I45: 1 | J45: 0
...

Sheet Biga Data
B2: Resumen!A1
B4: Plantilla de Gestión por Resultados de la Carrera Tecnología Superior en Big Data
C8: Actividades | H8: Producto finales | J8: Costo/Horas
B9: Estado | C9: Prioridad | D9: Fecha de entrega | E9: Tarea | F9: Docente Responsable | G9: Descripción | H9: Entregable | I9: % Ejecutado | J9: Costos fijos | K9: Horas estimadas | L9: Horas actuales | M9: Observación
B10: ESTRATEGIA 1 | E10: OBJETIVO OPERATIVO 1
B11: =FALSE() -> FALSE | C11: Media | D11: 2025-I ( Inicio ciclo) | E11: Planificar y estructurar las capacitaciones en el área técnica y didáctica. | F11: Director/a carrera Docentes | G11: Desarrollo del plan de capacitación docente | H11: Plan de capacitación docente. | I11: 1 | J11: 0 | T11: Alta
B12: =FALSE() -> FALSE | C12: Baja | D12: 2025-II ( fin ciclo) | E12: Ejecutar las capacitaciones planificadas. | F12: Director/a carrera Docentes | G12: informar sobre el plan de capacitación docente | H12: Informe de ejecución del plan de capacitación docente. | I12: 1 | J12: 0 | T12: Media
B13: =FALSE() -> FALSE | C13: Media | D13: 2024-II( fin ciclo) 2025-I( fin ciclo) | E13: Entregar los resultados de los procesos de Evaluación al desempeño Docente y acciones realizadas. | F13: Director/a carrera Docentes | G13: Generar una matriz para el registro de entrega de evaluaciones docentes | H13: Registro de entrega de evaluaciones a los docentes | I13: 1 | J13: 0 | T13: Baja
E14: OBJETIVO OPERATIVO 2
B15: =FALSE() -> FALSE | C15: Baja | D15: 2025-I (inicio ciclo) 2025-II(inicio ciclo) | E15: Socializar con los docentes el uso adecuado de la plataforma Moodle. | F15: Responsable de Moodle de la carrera | G15: Realizar la socialización y generar un informe sobre el uso del Moodle | H15: Informe de socialización / inducción a los docentes | I15: 1 | J15: 0
B16: =FALSE() -> FALSE | C16: Media | D16: 2024-II( fin ciclo) 2025-I( fin ciclo) | E16: Revisar el aporte de cada docente en la plataforma Moodle | F16: Responsable de Moodle de la carrera | G16: Controlar el uso adecuado de la plataforma y generar un informe. | H16: Informe de actividades en la plataforma Moodle. | I16: 1 | J16: 0
E17: OBJETIVO OPERATIVO 3
B18: =FALSE() -> FALSE | C18: Alta | D18: 2025-I(inicio ciclo) 2025-II (inicio ciclo) | E18: Planificar y desarrollar una reunión del colectivo académico | F18: Director/a carrera | G18: Realizar y evidenciar los colectivos académicos | H18: Convocatoria al colectivo de académico | I18: 0.5 | J18: 0 | M18: NO se localiza la convocatoria del ciclo académico 2025-II
B19: =FALSE() -> FALSE | C19: Media | D19: 2024-II(fin de ciclo) 2025-I(fin de ciclo) | E19: Revisión y actualización de los PEAS | F19: Director/a carrera Docentes | G19: Revisar si la bibliografía de la carrera es la adecuada en colectivos según PEAS y Colectivos para el acervo bibliográfico | H19: Acervo bibliográfico de todas las asignaturas de la carrera, Informes de colectivos y PEAS revisados | I19: 0.75 | J19: 0 | M19: NO se localiza el Acervo bibliográfico del ciclo académico 2025-II
B20: =FALSE() -> FALSE | C20: Media | D20: 2024-II(fin de ciclo) 2025-I(fin de ciclo) | E20: Actas de reunión por colectivo académico | F20: Director/a carrera Docentes | G20: Evidenciar el trabajo de colectivos | H20: Actas de colectivos | I20: 0.5 | J20: 0 | M20: NO se localizan las actas de colectivos del ciclo académico 2025-II
E21: OBJETIVO OPERATIVO 4
B22: =FALSE() -> FALSE | C22: Baja | D22: 2025-I(inicio ciclo) 2025-II (inicio ciclo) | E22: Recopilar las fichas de afinidad de los docentes de acuerdo al nivel de estudio. | F22: Director/a carrera | G22: Mantener actualizadas las fichas de afinidad de los docentes de acuerdo a la pertinencia en la carrera | H22: Fichas de afinidad de los docentes. | I22: 1 | J22: 0
C23: Alta | D23: 2025-I(inicio de ciclo) 2025-II(inicio de ciclo) | E23: Elaboración del distributivo docente de la carrera | F23: Director/a carrera | G23: Evidenciar la carga horaria y distributivos de los docentes | H23: Distributivo docente aprobado. | I23: 1 | J23: 0
B24: =FALSE() -> FALSE | C24: Media | D24: 2025-I(inicio de ciclo) 2025-II(inicio de ciclo) | E24: Designar responsables de la administración de la plataforma, tutorías , prácticas, vinculación , etc. | F24: Director/a carrera | G24: Realizar las designaciones y evidenciar los responsables y tutores de la carrera | H24: Oficios de designaciones de responsables. | I24: 1 | J24: 0
B25: ESTRATEGIA 2 | E25: OBJETIVO OPERATIVO 1
B26: =FALSE() -> FALSE | C26: Alta | D26: 2025-I(Inicio de ciclo) 2025-II(Inicio de ciclo) | E26: Elaborar y presentar el calendario de actividades de la o las carreras, horarios de clases y laboratorios. | F26: Director/a carrera | G26: Realizar los documentos necesarios para el desarrollo de las actividades de cada periodo de la carrera | H26: Calendario y horarios aprobados | I26: 1 | J26: 0
B27: =FALSE() -> FALSE | C27: Media | D27: 2025-I(Todo el ciclo) 2025-II(Todo de ciclo) | E27: Requerimiento y aprobación de Documentos académicos. (Sílabos, guías practicas e informes de avance de Silabo) | F27: Director/a carrera - gestor académico | G27: Solicitud de documentos académicos por materias | H27: Documentación aprobada. | I27: 0.5 | J27: 0 | M27: NO consta la documentación aprobada del ciclo académico 2025-II
B28: =FALSE() -> FALSE | C28: Media | D28: 2025-I(Todo el ciclo) 2025-II(Todo de ciclo) | E28: Seguimiento al cumplimiento de la documentación académica. | F28: Director/a carrera - gestor académico | G28: Revisión de documentos académicos por materias | H28: Informe de carrera sobre la documentación recibida. | I28: 0.5 | J28: 0 | M28: NO consta el informe de la documentación recibida del ciclo académico 2025-II
B29: =FALSE() -> FALSE | C29: Baja | D29: 2025-I(Todo el ciclo) 2025-II(Todo de ciclo) | E29: Reuniones de carrera para socialización y toma de decisiones | F29: Director/a carrera - gestor académico | G29: Reuniones de carrera de acuerdo a requerimientos | H29: Convocatorias, actas e informes de reuniones de carrera. | I29: 0.5 | J29: 0 | M29: NO consta la documentación del ciclo académico 2025-II
B30: =FALSE() -> FALSE | C30: Baja | D30: 45838 | E30: Informe semestral POA 2024 | F30: Director/a carrera - gestor académico | G30: Informar sobre el avance del POA | H30: Informe semestral seguimiento POA 2025 | I30: 1 | J30: 0
B31: =FALSE() -> FALSE | C31: Baja | D31: 45991 | E31: Informe final POA 2024 | F31: Director/a carrera - gestor académico | G31: Informar sobre el alcance final del POA | H31: Informe final POA 2025 | I31: 1 | J31: 0
B32: =FALSE() -> FALSE | C32: Baja | D32: 46011 | E32: Elaborar la Planificación Operativa Anual 2025 | F32: Director/a carrera - gestor académico | G32: Realizar la planificación para el 2026 | H32: POA 2026 | I32: 1 | J32: 0
B33: =FALSE() -> FALSE | C33: Media | D33: 2025-I (inicio de ciclo) 2025-II (inicio de ciclo) | E33: Designación de tutores de curso | F33: Director/a carrera | G33: Realizar las designaciones y evidenciar los responsables y tutores de la carrera | H33: Documento de designación de tutores por parte del director de carrera | I33: 1 | J33: 0
B34: =FALSE() -> FALSE | C34: Media | D34: 2025-I(Todo el ciclo) 2025-II(Todo el ciclo) | E34: Ejecutar las actividades de la fase de SEGUIMIENTO del modelo metodológico del proceso de Seguimiento Curricular | F34: Director/a de carrera - Gestor/a académico Tutores de curso | G34: Realizar el Seguimiento del modelo metodológico | H34: Fase SEGUIMIENTO: INICIO: Socialización de Tutorías Académicas DURANTE: Registro de Calificaciones del Primer Parcial FINAL : Registro de Calificación Finales | I34: 0.5 | J34: 0 | M34: NO consta la documentación del ciclo académico 2025-II
